# 下列代码的输出是什么？解释为什么那么输出

## 1.1

```
const promise = new Promise((resolve, reject) => {
  console.log(1);
  resolve('success')
  console.log(2);
});
promise.then(() => {
  console.log(3);
});
console.log(4);
```

作答：

```
输出结果： 1 2 4 3
代码自上向下的执行，因为Promise构造器内部的代码是同步执行的，所以先打印1，之后执行resolve，将success传递给then方法，但是Promise.then归属在微任务中，需要脚本完成执行后在执行，所以继续执行打印2，当完成promise的执行后在执行队列中还存在打印4的操作，所以打印出4。在4打印出来后宏任务执行完成，此时开始执行微任务，因此最后打印3.
```

## 1.2

```
const promise = new Promise((resolve, reject) => {
  console.log(1);
  console.log(2);
});
promise.then(() => {
  console.log(3);
});
console.log(4);
```

```
输出结果：1 2 4
代码自上向下的执行，因为Promise构造器内部的代码是同步执行的，所以先打印1和2，由于既没有执行resolve也没有执行reject，所以then不执行，不会产生微任务，接下来打印4
```

## 1.3

```
const promise1 = new Promise((resolve, reject) => {
  console.log('promise1')
  resolve('resolve1')
})
const promise2 = promise1.then(res => {
  console.log(res)
})
console.log('1', promise1);
console.log('2', promise2);
```

```
输出结果：
promise1
1 Promise { 'resolve1' }
2 Promise { <pending> }
resolve1

因为new Promise的构造函数是同步执行的，所以在将new Promise 赋值给promise1时，输出“promise1”，并且执行resolve。
promise1.then赋值给promse2的时候，then会进入微任务队列，等待脚本执行完毕后开始执行。
console.log('1', promise1)输出1以及promise1的状态，也就是说输出一个执行resolve的Promise。
console.log('2', promise2)输出2以及promise2的状态，因为then返回也是一个promise，同时因为then是微任务还未执行，所以此时promise2的promose状态是pending。
当脚本顺序执行完后检查微任务队列，此时微任务队列里有一个then等待执行，所以执行微任务，promise1的resolve返回“resolve1”，此时输出reslove1
```

## 1.4

```
const fn = () => (new Promise((resolve, reject) => {
  console.log(1);
  resolve('success')
}))
fn().then(res => {
  console.log(res)
})
console.log('start')
```

```
输出结果：
1 start success
```

## 1.5

```
const fn = () =>
  new Promise((resolve, reject) => {
    console.log(1);
    resolve("success");
  });
console.log("start");
fn().then(res => {
  console.log(res);
});
```

```
输出结果：
start 1 success
```

## 1.6

```
console.log('start')
setTimeout(() => {
  console.log('time')
})
Promise.resolve().then(() => {
  console.log('resolve')
})
console.log('end')
```

```
输出结果：
start end resolve time
```

## 1.7

```
const promise = new Promise((resolve, reject) => {
  console.log(1);
  setTimeout(() => {
    console.log("timerStart");
    resolve("success");
    console.log("timerEnd");
  }, 0);
  console.log(2);
});
promise.then((res) => {
  console.log(res);
});
console.log(4);

```

```
1 2 4 timerStart timerEnd success
```

## 1.8

```
setTimeout(() => {
  console.log('timer1');
  setTimeout(() => {
    console.log('timer3')
  }, 0)
}, 0)
setTimeout(() => {
  console.log('timer2')
}, 0)
console.log('start')
```

```
start timer1 timer2 timer3
```

## 1.9

```
setTimeout(() => {
  console.log('timer1');
  Promise.resolve().then(() => {
    console.log('promise')
  })
}, 0)
setTimeout(() => {
  console.log('timer2')
}, 0)
console.log('start')
```

```
start timer1 promise timer2
```

## 1.10

Promise.resolve().then(() => {
  console.log('promise1');
  const timer2 = setTimeout(() => {
    console.log('timer2')
  }, 0)
});
const timer1 = setTimeout(() => {
  console.log('timer1')
  Promise.resolve().then(() => {
    console.log('promise2')
  })
}, 0)
console.log('start');
```
start promise1 timer1 promise2 timer2

timer1在这里是一个定时器句柄，尽管它之后没有被显式地使用（比如通过clearTimeout(timer1)来清除），但并不影响定时器回调函数的执行。实际上，timer1变量存储了定时器的引用，但它仅用于如果我们需要取消定时器时能够找到对应的定时器实例。

由于JavaScript引擎的工作机制，输出顺序如下：
同步代码 console.log('start') 输出 "start"
微任务队列开始执行：
Promise.resolve().then 内的回调执行，输出 "promise1"
宏任务队列继续执行：
timer1 定时器回调执行，输出 "timer1" 并在其内部创建并立即resolve的Promise触发微任务
新产生的微任务执行，输出 "promise2"
继续宏任务队列：
timer2 定时器回调执行，输出 "timer2"
```
## 1.11

```
const promise1 = new Promise((resolve, reject) => {
  setTimeout(() => {
    resolve('success')
  }, 1000)
})
const promise2 = promise1.then(() => {
  throw new Error('error!!!')
})
console.log('promise1', promise1)
console.log('promise2', promise2)
setTimeout(() => {
  console.log('promise1', promise1)
  console.log('promise2', promise2)
}, 2000)
```
```
promise1 Promise { <pending> }
promise2 Promise { <pending> }
error
promise1 Promise { 'success' }
promise2 Promise { reject 'error' }
```
## 1.12

```
const promise1 = new Promise((resolve, reject) => {
  setTimeout(() => {
    resolve("success");
    console.log("timer1");
  }, 1000);
  console.log("promise1里的内容");
});
const promise2 = promise1.then(() => {
  throw new Error("error!!!");
});
console.log("promise1", promise1);
console.log("promise2", promise2);
setTimeout(() => {
  console.log("timer2");
  console.log("promise1", promise1);
  console.log("promise2", promise2);
}, 2000);
```
```
promise1里的内容
promise1 Promise { <pending> }
promise2 Promise { <pending> }
timer1
error
timer2
promise1 Promise { 'success' }
promise2 Promise { error }
```
## 1.13

```
const promise = new Promise((resolve, reject) => {
  resolve("success1");
  reject("error");
  resolve("success2");
});
promise
.then(res => {
    console.log("then: ", res);
  }).catch(err => {
    console.log("catch: ", err);
  })
```
```
then: success1
```
## 1.14

```
const promise = new Promise((resolve, reject) => {
  reject("error");
  resolve("success2");
});
promise
.then(res => {
    console.log("then1: ", res);
  }).then(res => {
    console.log("then2: ", res);
  }).catch(err => {
    console.log("catch: ", err);
  }).then(res => {
    console.log("then3: ", res);
  })
```
```
catch: error
then3: undefined
```
## 1.15

```
Promise.resolve(1)
  .then(res => {
    console.log(res);
    return 2;
  })
  .catch(err => {
    return 3;
  })
  .then(res => {
    console.log(res);
  });
```
```
1 2
```
## 1.16

```
Promise.reject(1)
  .then(res => {
    console.log(res);
    return 2;
  })
  .catch(err => {
    console.log(err);
    return 3
  })
  .then(res => {
    console.log(res);
  });
```
```
1 3
```
## 1.17

```
const promise = new Promise((resolve, reject) => {
  setTimeout(() => {
    console.log('timer')
    resolve('success')
  }, 1000)
})
const start = Date.now();
promise.then(res => {
  console.log(res, Date.now() - start)
})
promise.then(res => {
  console.log(res, Date.now() - start)
})
```
```
timer
success 1000
success 1000
```
## 1.18

```
Promise.resolve().then(() => {
  return new Error('error!!!')
}).then(res => {
  console.log("then: ", res)
}).catch(err => {
  console.log("catch: ", err)
})
```
```
catch: Error
```
## 1.19

```
const promise = Promise.resolve().then(() => {
  return promise;
})
promise.catch(console.err)
```
```
TypeError: Promise的循环引用
```
## 1.20

```
Promise.resolve(1)
  .then(2)
  .then(Promise.resolve(3))
  .then(console.log)
```
```
1

Promise.resolve(1) 创建并立即解决一个Promise，其值为1。
第一个.then(2)传入的不是一个函数而是数值2，根据Promise/A+规范，非函数作为.then()的回调会被忽略，所以这里实际并未改变Promise的值，它仍然保持为1。
第二个.then(Promise.resolve(3))虽然传入的是Promise.resolve(3)，但因为在上一个.then()中未正确处理Promise结果导致Promise的值没有改变，所以这里的Promise.resolve(3)也不会执行，Promise的值依然为1。
最后的.then(console.log)接收到了上一个Promise的解决值1，并通过console.log将其打印到控制台
```
## 1.21

```
Promise.reject('err!!!')
  .then((res) => {
    console.log('success', res)
  }, (err) => {
    console.log('error', err)
  }).catch(err => {
    console.log('catch', err)
  })
```
```
error err!!
```
## 1.22

```
Promise.resolve()
  .then(function success (res) {
    throw new Error('error!!!')
  }, function fail1 (err) {
    console.log('fail1', err)
  }).catch(function fail2 (err) {
    console.log('fail2', err)
  })
```
```
fail2 Error: error!!!
```
## 1.23

```
Promise.resolve('1')
  .then(res => {
    console.log(res)
  })
  .finally(() => {
    console.log('finally')
  })
Promise.resolve('2')
  .finally(() => {
    console.log('finally2')
  	return '我是finally2返回的值'
  })
  .then(res => {
    console.log('finally2后面的then函数', res)
  })
```
```
1
finally2
finally
finally2后面的then函数 2
```
## 1.24

```
Promise.resolve('1')
  .finally(() => {
    console.log('finally1')
    throw new Error('我是finally中抛出的异常')
  })
  .then(res => {
    console.log('finally后面的then函数', res)
  })
  .catch(err => {
    console.log('捕获错误', err)
  })
```
```
finally1
捕获错误 Error: 我是finally中抛出的异常
```
## 1.25

```
function promise1 () {
  let p = new Promise((resolve) => {
    console.log('promise1');
    resolve('1')
  })
  return p;
}
function promise2 () {
  return new Promise((resolve, reject) => {
    reject('error')
  })
}
promise1()
  .then(res => console.log(res))
  .catch(err => console.log(err))
  .finally(() => console.log('finally1'))

promise2()
  .then(res => console.log(res))
  .catch(err => console.log(err))
  .finally(() => console.log('finally2'))
```
```
promise1
1
error
finally1
finally2
```
## 1.26

```
function runAsync (x) {
    const p = new Promise(r => setTimeout(() => r(x, console.log(x)), 1000))
    return p
}
Promise.all([runAsync(1), runAsync(2), runAsync(3)])
  .then(res => console.log(res))
```
```
1
2
3
[1, 2, 3]
```
## 1.27

```
function runAsync (x) {
  const p = new Promise(r => setTimeout(() => r(x, console.log(x)), 1000))
  return p
}
function runReject (x) {
  const p = new Promise((res, rej) => setTimeout(() => rej(`Error: ${x}`, console.log(x)), 1000 * x))
  return p
}
Promise.all([runAsync(1), runReject(4), runAsync(3), runReject(2)])
  .then(res => console.log(res))
  .catch(err => console.log(err))
```
```
1
3
2
Error: 2
4
```
## 1.28

```
function runAsync (x) {
  const p = new Promise(r => setTimeout(() => r(x, console.log(x)), 1000))
  return p
}
Promise.race([runAsync(1), runAsync(2), runAsync(3)])
  .then(res => console.log('result: ', res))
  .catch(err => console.log(err))
```
```
1
result: 1
2
3
```
## 1.29

```
function runAsync(x) {
  const p = new Promise(r =>
    setTimeout(() => r(x, console.log(x)), 1000)
  );
  return p;
}
function runReject(x) {
  const p = new Promise((res, rej) =>
    setTimeout(() => rej(`Error: ${x}`, console.log(x)), 1000 * x)
  );
  return p;
}
Promise.race([runReject(0), runAsync(1), runAsync(2), runAsync(3)])
  .then(res => console.log("result: ", res))
  .catch(err => console.log(err));
```
```
0
Error: 0
1
2
3
```
## 1.30

```
async function async1() {
  console.log("async1 start");
  await async2();
  console.log("async1 end");
}
async function async2() {
  console.log("async2");
}
async1();
console.log('start')
```
```
async1 start
async2
start
async1 end

在 JavaScript 中，async 函数会返回一个 Promise 对象。当执行到 await 关键字时，JavaScript 引擎会暂停执行该 async 函数，等待 await 后面的表达式执行完成。然而，这并不会阻止后续代码的执行，而是会让出执行权，让主程序继续执行。

所以在这段代码中，当执行到 await async2() 时，会暂停 async1() 函数的执行，然后执行 console.log('start')，输出 "start"。接着，async2() 函数执行完成，再恢复执行 async1() 函数，输出 "async1 end"。

执行函数中的同步代码async1 start，之后碰到了await，它会阻塞async1后面代码的执行，因此会先去执行async2中的同步代码async2，然后跳出async1
跳出async1函数后，执行同步代码start
在一轮宏任务全部执行完之后，再来执行刚刚await后面的内容async1 end。

「紧跟着await后面的语句相当于放到了new Promise中，下一行及之后的语句相当于放在Promise.then中」
```
## 1.31

```
async function async1() {
  console.log("async1 start");
  new Promise(resolve => {
    console.log('promise')
  })
  console.log("async1 end");
}
async1();
console.log("start")
```
```
async1 start
promise
async1 end
start
```
## 1.32

```
async function async1() {
  console.log("async1 start");
  await async2();
  console.log("async1 end");
}
async function async2() {
  setTimeout(() => {
    console.log('timer')
  }, 0)
  console.log("async2");
}
async1();
console.log("start")
```
```
async1 start
async2
start
async1 end
timer
```
## 1.33

```
async function async1() {
  console.log("async1 start");
  await async2();
  console.log("async1 end");
  setTimeout(() => {
    console.log('timer1')
  }, 0)
}
async function async2() {
  setTimeout(() => {
    console.log('timer2')
  }, 0)
  console.log("async2");
}
async1();
setTimeout(() => {
  console.log('timer3')
}, 0)
console.log("start")
```

```
async1 start
async2
start
async1 end
timer2
timer3
timer1
```
## 1.34

```
async function fn () {
  // return await 1234
  // 等同于
  return 123
}
fn().then(res => console.log(res))
```
```
123
```
## 1.35

```
async function async1 () {
  console.log('async1 start');
  await new Promise(resolve => {
    console.log('promise1')
  })
  console.log('async1 success');
  return 'async1 end'
}
console.log('srcipt start')
async1().then(res => console.log(res))
console.log('srcipt end')
```
```
srcipt start
async1 start
promise1
srcipt end

在async1中await后面的Promise是没有返回值的，也就是它的状态始终是pending状态，因此相当于一直在await，await，await却始终没有响应...
```
## 1.36

```
async function async1 () {
  console.log('async1 start');
  await new Promise(resolve => {
    console.log('promise1')
    resolve('promise1 resolve')
  }).then(res => console.log(res))
  console.log('async1 success');
  return 'async1 end'
}
console.log('srcipt start')
async1().then(res => console.log(res))
console.log('srcipt end')
```
```
script start
async1 start
promise1
script end
promise1 resolve
async1 success
async1 end
```
## 1.37

```
async function async1 () {
  console.log('async1 start');
  await new Promise(resolve => {
    console.log('promise1')
    resolve('promise resolve')
  })
  console.log('async1 success');
  return 'async1 end'
}
console.log('srcipt start')
async1().then(res => {
  console.log(res)
})
new Promise(resolve => {
  console.log('promise2')
  setTimeout(() => {
    console.log('timer')
  })
})
```
```
script start
async1 start
promise1
promise2
async1 success
async1 end
timer
```
## 1.38

```
async function async1() {
  console.log("async1 start");
  await async2();
  console.log("async1 end");
}

async function async2() {
  console.log("async2");
}

console.log("script start");

setTimeout(function() {
  console.log("setTimeout");
}, 0);

async1();

new Promise(function(resolve) {
  console.log("promise1");
  resolve();
}).then(function() {
  console.log("promise2");
});
console.log('script end')
```
```
script start
async1 start
async2
promise1
script end
async1 end
promise2
setTimeout
```
## 1.39

```
async function testSometing() {
  console.log("执行testSometing");
  return "testSometing";
}

async function testAsync() {
  console.log("执行testAsync");
  return Promise.resolve("hello async");
}

async function test() {
  console.log("test start...");
  const v1 = await testSometing();
  console.log(v1);
  const v2 = await testAsync();
  console.log(v2);
  console.log(v1, v2);
}

test();

var promise = new Promise(resolve => {
  console.log("promise start...");
  resolve("promise");
});
promise.then(val => console.log(val));

console.log("test end...");
```
```
test start...
执行testSometing
promise start...
test end...
testSometing
执行testAsync 
promise
hello async 
testSometing hello async
```
## 1.40

```
async function async1 () {
  await async2();
  console.log('async1');
  return 'async1 success'
}
async function async2 () {
  return new Promise((resolve, reject) => {
    console.log('async2')
    reject('error')
  })
}
async1().then(res => console.log(res))
```
```
async2
Promise {<rejected>: 'error'}
```
## 1.41

```
async function async1 () {
  try {
    await Promise.reject('error!!!')
  } catch(e) {
    console.log(e)
  }
  console.log('async1');
  return Promise.resolve('async1 success')
}
async1().then(res => console.log(res))
console.log('script start')
```
```
script start
error!!!
async1
async1 success
```
## 1.42

```
const first = () => (new Promise((resolve, reject) => {
    console.log(3);
    let p = new Promise((resolve, reject) => {
        console.log(7);
        setTimeout(() => {
            console.log(5);
            resolve(6);
            console.log(p)
        }, 0)
        resolve(1);
    });
    resolve(2);
    p.then((arg) => {
        console.log(arg);
    });
}));
first().then((arg) => {
    console.log(arg);
});
console.log(4);
```
```
3
7
4
1
2
5
Promsise {1}
```
## 1.43

```
const async1 = async () => {
  console.log('async1');
  setTimeout(() => {
    console.log('timer1')
  }, 2000)
  await new Promise(resolve => {
    console.log('promise1')
  })
  console.log('async1 end')
  return 'async1 success'
} 
console.log('script start');
async1().then(res => console.log(res));
console.log('script end');
Promise.resolve(1)
  .then(2)
  .then(Promise.resolve(3))
  .catch(4)
  .then(res => console.log(res))
setTimeout(() => {
  console.log('timer2')
}, 1000)
```
```
script start
async1
promise1
script end
1
timer2
timer1
```
## 1.44

```
const p1 = new Promise((resolve) => {
  setTimeout(() => {
    resolve('resolve3');
    console.log('timer1')
  }, 0)
  resolve('resovle1');
  resolve('resolve2');
}).then(res => {
  console.log(res)
  setTimeout(() => {
    console.log(p1)
  }, 1000)
}).finally(res => {
  console.log('finally', res)
})
```
```
resolve1
finally undefined
timer1
Promise { undefined }

Promise的状态一旦改变就无法改变(类似题目3.5)
finally不管Promise的状态是resolved还是rejected都会执行，且它的回调函数是接收不到Promise的结果的，所以finally()中的res是一个迷惑项(类似3.10)。
最后一个定时器打印出的p1其实是.finally的返回值，我们知道.finally的返回值如果在没有抛出错误的情况下默认会是上一个Promise的返回值(3.10中也有提到), 而这道题中.finally上一个Promise是.then()，但是这个.then()并没有返回值，所以p1打印出来的Promise的值会是undefined，如果你在定时器的下面加上一个return 1，则值就会变成1
```
## 1.45、使用Promise实现每隔1秒输出1,2,3

```

```
## 1.46、使用Promise实现红绿灯交替重复亮

```

```
## 1.47、 封装一个异步加载图片的方法

```

```
## 1.48、限制异步操作的并发个数并尽可能快的完成全部

```

```
